Traceback (most recent call last):
  File "/opt/hostedtoolcache/Python/3.11.13/x64/lib/python3.11/site-packages/jupyter_cache/executors/utils.py", line 58, in single_nb_execution
    executenb(
  File "/opt/hostedtoolcache/Python/3.11.13/x64/lib/python3.11/site-packages/nbclient/client.py", line 1319, in execute
    return NotebookClient(nb=nb, resources=resources, km=km, **kwargs).execute()
           ^^^^^^^^^^^^^^^^^^^^^^^^^^^^^^^^^^^^^^^^^^^^^^^^^^^^^^^^^^^^^^^^^^^^^
  File "/opt/hostedtoolcache/Python/3.11.13/x64/lib/python3.11/site-packages/jupyter_core/utils/__init__.py", line 165, in wrapped
    return loop.run_until_complete(inner)
           ^^^^^^^^^^^^^^^^^^^^^^^^^^^^^^
  File "/opt/hostedtoolcache/Python/3.11.13/x64/lib/python3.11/asyncio/base_events.py", line 654, in run_until_complete
    return future.result()
           ^^^^^^^^^^^^^^^
  File "/opt/hostedtoolcache/Python/3.11.13/x64/lib/python3.11/site-packages/nbclient/client.py", line 709, in async_execute
    await self.async_execute_cell(
  File "/opt/hostedtoolcache/Python/3.11.13/x64/lib/python3.11/site-packages/nbclient/client.py", line 1062, in async_execute_cell
    await self._check_raise_for_error(cell, cell_index, exec_reply)
  File "/opt/hostedtoolcache/Python/3.11.13/x64/lib/python3.11/site-packages/nbclient/client.py", line 918, in _check_raise_for_error
    raise CellExecutionError.from_cell_and_msg(cell, exec_reply_content)
nbclient.exceptions.CellExecutionError: An error occurred while executing the following cell:
------------------
G.remove_edge(2, 5)
------------------


[31m---------------------------------------------------------------------------[39m
[31mKeyError[39m                                  Traceback (most recent call last)
[36mFile [39m[32m/opt/hostedtoolcache/Python/3.11.13/x64/lib/python3.11/site-packages/networkx/classes/graph.py:1134[39m, in [36mGraph.remove_edge[39m[34m(self, u, v)[39m
[32m   1133[39m [38;5;28;01mtry[39;00m:
[32m-> [39m[32m1134[39m     [38;5;28;01mdel[39;00m [38;5;28;43mself[39;49m[43m.[49m[43m_adj[49m[43m[[49m[43mu[49m[43m][49m[43m[[49m[43mv[49m[43m][49m
[32m   1135[39m     [38;5;28;01mif[39;00m u != v:  [38;5;66;03m# self-loop needs only one entry removed[39;00m

[31mKeyError[39m: 5

The above exception was the direct cause of the following exception:

[31mNetworkXError[39m                             Traceback (most recent call last)
[36mCell[39m[36m [39m[32mIn[23][39m[32m, line 1[39m
[32m----> [39m[32m1[39m [43mG[49m[43m.[49m[43mremove_edge[49m[43m([49m[32;43m2[39;49m[43m,[49m[43m [49m[32;43m5[39;49m[43m)[49m

[36mFile [39m[32m/opt/hostedtoolcache/Python/3.11.13/x64/lib/python3.11/site-packages/networkx/classes/graph.py:1138[39m, in [36mGraph.remove_edge[39m[34m(self, u, v)[39m
[32m   1136[39m         [38;5;28;01mdel[39;00m [38;5;28mself[39m._adj[v][u]
[32m   1137[39m [38;5;28;01mexcept[39;00m [38;5;167;01mKeyError[39;00m [38;5;28;01mas[39;00m err:
[32m-> [39m[32m1138[39m     [38;5;28;01mraise[39;00m NetworkXError([33mf[39m[33m"[39m[33mThe edge [39m[38;5;132;01m{[39;00mu[38;5;132;01m}[39;00m[33m-[39m[38;5;132;01m{[39;00mv[38;5;132;01m}[39;00m[33m is not in the graph[39m[33m"[39m) [38;5;28;01mfrom[39;00m[38;5;250m [39m[34;01merr[39;00m
[32m   1139[39m nx._clear_cache([38;5;28mself[39m)

[31mNetworkXError[39m: The edge 2-5 is not in the graph

