Traceback (most recent call last):
  File "/opt/hostedtoolcache/Python/3.11.9/x64/lib/python3.11/site-packages/jupyter_cache/executors/utils.py", line 58, in single_nb_execution
    executenb(
  File "/opt/hostedtoolcache/Python/3.11.9/x64/lib/python3.11/site-packages/nbclient/client.py", line 1314, in execute
    return NotebookClient(nb=nb, resources=resources, km=km, **kwargs).execute()
           ^^^^^^^^^^^^^^^^^^^^^^^^^^^^^^^^^^^^^^^^^^^^^^^^^^^^^^^^^^^^^^^^^^^^^
  File "/opt/hostedtoolcache/Python/3.11.9/x64/lib/python3.11/site-packages/jupyter_core/utils/__init__.py", line 165, in wrapped
    return loop.run_until_complete(inner)
           ^^^^^^^^^^^^^^^^^^^^^^^^^^^^^^
  File "/opt/hostedtoolcache/Python/3.11.9/x64/lib/python3.11/asyncio/base_events.py", line 654, in run_until_complete
    return future.result()
           ^^^^^^^^^^^^^^^
  File "/opt/hostedtoolcache/Python/3.11.9/x64/lib/python3.11/site-packages/nbclient/client.py", line 709, in async_execute
    await self.async_execute_cell(
  File "/opt/hostedtoolcache/Python/3.11.9/x64/lib/python3.11/site-packages/nbclient/client.py", line 1062, in async_execute_cell
    await self._check_raise_for_error(cell, cell_index, exec_reply)
  File "/opt/hostedtoolcache/Python/3.11.9/x64/lib/python3.11/site-packages/nbclient/client.py", line 918, in _check_raise_for_error
    raise CellExecutionError.from_cell_and_msg(cell, exec_reply_content)
nbclient.exceptions.CellExecutionError: An error occurred while executing the following cell:
------------------
G.remove_edge(2, 5)
------------------


[0;31m---------------------------------------------------------------------------[0m
[0;31mKeyError[0m                                  Traceback (most recent call last)
File [0;32m/opt/hostedtoolcache/Python/3.11.9/x64/lib/python3.11/site-packages/networkx/classes/graph.py:1127[0m, in [0;36mGraph.remove_edge[0;34m(self, u, v)[0m
[1;32m   1126[0m [38;5;28;01mtry[39;00m:
[0;32m-> 1127[0m     [38;5;28;01mdel[39;00m [38;5;28;43mself[39;49m[38;5;241;43m.[39;49m[43m_adj[49m[43m[[49m[43mu[49m[43m][49m[43m[[49m[43mv[49m[43m][49m
[1;32m   1128[0m     [38;5;28;01mif[39;00m u [38;5;241m!=[39m v:  [38;5;66;03m# self-loop needs only one entry removed[39;00m

[0;31mKeyError[0m: 5

The above exception was the direct cause of the following exception:

[0;31mNetworkXError[0m                             Traceback (most recent call last)
Cell [0;32mIn[23], line 1[0m
[0;32m----> 1[0m [43mG[49m[38;5;241;43m.[39;49m[43mremove_edge[49m[43m([49m[38;5;241;43m2[39;49m[43m,[49m[43m [49m[38;5;241;43m5[39;49m[43m)[49m

File [0;32m/opt/hostedtoolcache/Python/3.11.9/x64/lib/python3.11/site-packages/networkx/classes/graph.py:1131[0m, in [0;36mGraph.remove_edge[0;34m(self, u, v)[0m
[1;32m   1129[0m         [38;5;28;01mdel[39;00m [38;5;28mself[39m[38;5;241m.[39m_adj[v][u]
[1;32m   1130[0m [38;5;28;01mexcept[39;00m [38;5;167;01mKeyError[39;00m [38;5;28;01mas[39;00m err:
[0;32m-> 1131[0m     [38;5;28;01mraise[39;00m NetworkXError([38;5;124mf[39m[38;5;124m"[39m[38;5;124mThe edge [39m[38;5;132;01m{[39;00mu[38;5;132;01m}[39;00m[38;5;124m-[39m[38;5;132;01m{[39;00mv[38;5;132;01m}[39;00m[38;5;124m is not in the graph[39m[38;5;124m"[39m) [38;5;28;01mfrom[39;00m [38;5;21;01merr[39;00m
[1;32m   1132[0m nx[38;5;241m.[39m_clear_cache([38;5;28mself[39m)

[0;31mNetworkXError[0m: The edge 2-5 is not in the graph

